Workbook
Name _PAR1: '[1]Nathal 2009'!$H$14:$R$16
Name _PAR1: '[1]Nathal 2009'!$H$14:$R$16
Name _PAR1: '[1]Nathal 2009'!$H$14:$R$16
Name _PAR1: '[1]Nathal 2009'!$H$14:$R$16
Name _PAR1: '[1]Nathal 2009'!$H$14:$R$16
Name _PAR1: '[2]Nathal 2009'!$H$14:$R$16
Name asd: #REF!
Name BASE: '[3]Base Control'!$C$5:$CH$104
Name CLIENTES: '[1]CLIENTES_11-08'!$A$3:$IV$1001
Name CLIENTES: '[1]CLIENTES_11-08'!$A$3:$IV$1001
Name CLIENTES: '[1]CLIENTES_11-08'!$A$3:$IV$1001
Name CLIENTES: '[1]CLIENTES_11-08'!$A$3:$IV$1001
Name CLIENTES: '[1]CLIENTES_11-08'!$A$3:$IV$1001
Name CLIENTES: '[2]CLIENTES_11-08'!$3:$1001
Name Clientes1: [4]CLIENTES_NATHAL!$A$3:$IV$1001
Name Clientes1: [4]CLIENTES_NATHAL!$A$3:$IV$1001
Name Clientes1: [4]CLIENTES_NATHAL!$A$3:$IV$1001
Name Clientes1: [4]CLIENTES_NATHAL!$A$3:$IV$1001
Name Clientes1: [4]CLIENTES_NATHAL!$A$3:$IV$1001
Name Clientes1: [4]CLIENTES_NATHAL!$3:$1001
Name klñkm: #REF!
Name klñkm: #REF!
Name klñkm: #REF!
Name klñkm: #REF!
Name klñkm: #REF!
Name klñkm: #REF!
Name M_Empresas: '[3]Base Control'!$C$5:$C$104
Name tabla: #REF!
Name tabla: #REF!
Name tabla: #REF!
Name tabla: #REF!
Name tabla: #REF!
Name tabla: #REF!

Sheet Activos 2022
B2: Núm. Nómina | C2: Número de Seguro Social (11 Dígitos) | D2: Sexo (M , F) | E2: RFC | F2: Fecha de Nacimiento (dd/mm/aaaa) | G2: Fecha de Ingreso Reconocida (dd/mm/aaaa) | H2: Salario integrado
B3: 0000002 | C3: 70886511255 | D3: M | E3: GUFF650507RE7 | F3: 650507 | G3: 04/02/1992 | H3: 214815.92
B4: 0000003 | C4: 45927277983 | D4: M | E4: ROMA7208057B3 | F4: 720805 | G4: 01/07/1992 | H4: 16009.248
B5: 0000004 | C5: 64866912112 | D5: M | E5: PAMN690418F47 | F5: 690418 | G5: 15/11/1992 | H5: 20168.576
B6: 0000005 | C6: 45947200825 | D6: F | E6: GAGS720516D59 | F6: 720516 | G6: 18/07/1994 | H6: 11524.336
B7: 0000007 | C7: 11886402442 | D7: F | E7: VIBG640904TE1 | F7: 640904 | G7: 28/11/1996 | H7: 12877.44
B8: 0000009 | C8: 28957509293 | D8: F | E8: VIRA750319CJ0 | F8: 750319 | G8: 04/05/1998 | H8: 44069.36
B9: 0000013 | C9: 01987103247 | D9: M | E9: GAVA711112CU4 | F9: 711112 | G9: 26/04/1999 | H9: 17722.896
B10: 0000018 | C10: 45996202714 | D10: F | E10: ROLA620912575 | F10: 620912 | G10: 01/11/1999 | H10: 88054.895
B11: 0000020 | C11: 76007400534 | D11: F | E11: PIMA740526PT6 | F11: 740526 | G11: 05/04/2000 | H11: 29757.648
B12: 0000026 | C12: 14926809337 | D12: M | E12: BAVJ6803186N3 | F12: 680318 | G12: 15/02/2001 | H12: 56417.232
B13: 0000032 | C13: 30947526080 | D13: F | E13: HESD751222DX4 | F13: 751222 | G13: 11/03/2002 | H13: 24313.008
B14: 0000033 | C14: 90917348667 | D14: F | E14: OEMF730618FR9 | F14: 730618 | G14: 11/03/2002 | H14: 17233.456
... B886: 0006454 | C886: 96149956649 | D886: F | E886: RONL9909054I6 | F886: 990905 | G886: 03/10/2022 | H886: 6661.856
B887: 0000138 | C887: 88835906012 | D887: F | E887: HEEA590522219 | F887: 590522 | G887: 35856 | H887: 178171.72
B888: 0000881 | C888: 90047202099 | D888: M | E888: SALU720818UYA | F888: 720818 | G888: 02/01/2018 | H888: 178628.19
B889: 0001502 | C889: 39927339398 | D889: M | E889: AAPJ730716BK0 | F889: 730716 | G889: 01/06/2018 | H889: 243943.56
B890: 0001786 | C890: 07997502146 | D890: M | E890: LAUV750221TG4 | F890: 750221 | G890: 15/06/2017 | H890: 359677.27
B891: 0001788 | C891: 65917113709 | D891: F | E891: PORA710201KZ0 | F891: 710201 | G891: 02/08/2021 | H891: 143278.85
B892: 0001789 | C892: 64856408873 | D892: M | E892: PIGR640329Q61 | F892: 640329 | G892: 01/06/2017 | H892: 546673.14
B893: 0002301 | C893: 45936714497 | D893: F | E893: CASA670424SD0 | F893: 670424 | G893: 16/10/1999 | H893: 13463.248
B894: 0002308 | C894: 94098721007 | D894: F | E894: AUBM8702271F2 | F894: 870227 | G894: 17/09/2009 | H894: 6413.792
B895: 0002314 | C895: 28098803191 | D895: F | E895: TOBM880102546 | F895: 880102 | G895: 16/01/2012 | H895: 6413.792
B896: 0002330 | C896: 30917212927 | D896: M | E896: PASA720805RS0 | F896: 720805 | G896: 01/08/2016 | H896: 18014.736
B897: 0002336 | C897: 45078816407 | D897: F | E897: CUGM880105NJ6 | F897: 880105 | G897: 18/10/2016 | H897: 9307.568
B898: 0002337 | C898: 45128902611 | D898: M | E898: AAGD890519SL2 | F898: 890519 | G898: 02/01/2017 | H898: 16143.616
B899: 0002338 | C899: 37967310519 | D899: M | E899: MAGM7303174T0 | F899: 730317 | G899: 20/01/2017 | H899: 6843.04
... B916: 0000593 | C916: 12977347751 | D916: M | E916: RORA760321A25 | F916: 760321 | G916: 15/12/2020 | H916: 37798.144

Sheet Bajas 2022
B2: Núm. Nómina | C2: Sexo (M , F) | D2: RFC | E2: Fecha de Nacimiento (dd/mm/aaaa) | F2: Fecha de Ingreso Reconocida (dd/mm/aaaa) | G2: Fecha de Baja (dd/mm/aaaa) | H2: Salario integrado | I2: Monto por Prima de Antigüedad | J2: Monto por Indemnización | K2: (*)Causa de Baja
B3: 0001041 | C3: F | D3: AEGN900917D96 | E3: 900917 | F3: 19/07/2021 | G3: 13/09/2021 | K3: TERMINACION DE CONTRATO
B4: 0005137 | C4: M | D4: BAHA9904275Z6 | E4: 990427 | F4: 16/02/2021 | G4: 17/09/2021 | K4: RENUNCIA VOLUNTARIA
B5: 0005495 | C5: M | D5: BUGA890707JL7 | E5: 890707 | F5: 23/08/2021 | G5: 13/09/2021 | K5: RENUNCIA VOLUNTARIA
B6: 0005479 | C6: F | D6: CAOJ9512214Z0 | E6: 951221 | F6: 16/08/2021 | G6: 17/09/2021 | K6: TERMINACION DE CONTRATO
B7: 0003496 | C7: F | D7: CUCG851123UN5 | E7: 851123 | F7: 17/02/2020 | G7: 18/09/2021 | K7: RENUNCIA VOLUNTARIA
B8: 0005468 | C8: F | D8: GURI910712FD4 | E8: 910712 | F8: 17/08/2021 | G8: 13/09/2021 | K8: RENUNCIA VOLUNTARIA
B9: 0000406 | C9: M | D9: HEJP870926J53 | E9: 870926 | F9: 20/05/2014 | G9: 07/06/2021 | K9: RENUNCIA VOLUNTARIA
B10: 0005422 | C10: F | D10: MORN850119N52 | E10: 850119 | F10: 13/07/2021 | G10: 13/09/2021 | K10: RENUNCIA VOLUNTARIA
B11: 0000072 | C11: F | D11: RADF621028F48 | E11: 621028 | F11: 13/07/2021 | G11: 13/09/2021 | K11: RENUNCIA VOLUNTARIA
B12: 0001981 | C12: F | D12: VAMV7408181J1 | E12: 740818 | F12: 26/01/2019 | G12: 17/09/2021 | K12: RENUNCIA VOLUNTARIA
B13: 0005252 | C13: M | D13: CALF910125MA1 | E13: 910125 | F13: 05/05/2021 | G13: 13/09/2021 | K13: RENUNCIA VOLUNTARIA
B14: 0002150 | C14: F | D14: MECL9109266F2 | E14: 910926 | F14: 25/09/2018 | G14: 21/09/2021 | K14: RENUNCIA VOLUNTARIA
... B24: 0004741 | C24: M | D24: POGF910924EJ8 | E24: 910924 | F24: 03/08/2020 | G24: 13/10/2021 | K24: RECISION CONTRATO
B25: 0002201 | C25: M | D25: SAMM630705N25 | E25: 630705 | F25: 05/10/2018 | G25: 44484 | K25: RENUNCIA VOLUNTARIA
B26: 0004709 | C26: M | D26: BEGG960127R92 | E26: 960127 | F26: 07/07/2020 | G26: 30/09/2021 | H26: 7147.04 | I26: 2600 | J26: 7053.06 | K26: RECISION CONTRATO
B27: 0004982 | C27: F | D27: BAHA990308IK0 | E27: 990308 | F27: 16/10/2020 | G27: 20/10/2021 | H27: 6079.088 | I27: 5919.45 | J27: 17997.53 | K27: RECISION CONTRATO
B28: 0004978 | C28: M | D28: ZAAC971219MI5 | E28: 971219 | F28: 14/10/2020 | G28: 20/10/2021 | H28: 5776 | I28: 5720 | J28: 17100 | K28: RECISION CONTRATO
B29: 0005296 | C29: M | D29: MEVJ971222ML9 | E29: 971222 | F29: 27/05/2021 | G29: 27/10/2021 | H29: 5158.88 | I29: 0 | J29: 15272.88 | K29: RECISION CONTRATO
B30: 0005301 | C30: M | D30: BANJ020506JZ8 | E30: 020506 | F30: 28/05/2021 | G30: 27/10/2021 | H30: 5125.44 | I30: 0 | J30: 15174.25 | K30: RECISION CONTRATO
B31: 0005500 | C31: F | D31: GASB971030T81 | E31: 971030 | F31: 30/08/2021 | G31: 29/09/2021 | K31: TERMINACION DE CONTRATO
B32: 0000990 | C32: F | D32: GAGJ981129N36 | E32: 981129 | F32: 02/05/2018 | G32: 19/10/2021 | K32: RENUNCIA VOLUNTARIA
B33: 0004967 | C33: M | D33: HEDL961122M27 | E33: 961122 | F33: 16/10/2020 | G33: 30/10/2021 | K33: RENUNCIA VOLUNTARIA
B34: 0005668 | C34: F | D34: OECF931209A38 | E34: 931209 | F34: 19/10/2021 | G34: 03/11/2021 | K34: RENUNCIA VOLUNTARIA
B35: 0005175 | C35: F | D35: VIQA910308R7A | E35: 910308 | F35: 10/03/2021 | G35: 19/10/2021 | K35: RENUNCIA VOLUNTARIA
B36: 0005328 | C36: M | D36: REGO970510GQ0 | E36: 970510 | F36: 10/06/2021 | G36: 05/11/2021 | K36: RENUNCIA VOLUNTARIA
B37: 0005475 | C37: F | D37: AARR910321A79 | E37: 910321 | F37: 09/08/2021 | G37: 16/11/2021 | K37: RENUNCIA VOLUNTARIA
B38: 0002038 | C38: M | D38: GUCR791122V78 | E38: 791122 | F38: 20/09/2021 | G38: 05/11/2021 | K38: RENUNCIA VOLUNTARIA
B39: 0004595 | C39: M | D39: TEMG8905131U5 | E39: 890513 | F39: 12/03/2020 | G39: 29/10/2021 | K39: RENUNCIA VOLUNTARIA
B40: 0005230 | C40: F | D40: ROFA870828AU4 | E40: 870828 | F40: 26/04/2021 | G40: 07/10/2021 | K40: RENUNCIA VOLUNTARIA
B41: 0000109 | C41: M | D41: MOME7107284E3 | E41: 710728 | F41: 27/05/2008 | G41: 08/12/2021 | H41: 8510.48 | I41: 114297.69 | J41: 25195.36 | K41: RECISION CONTRATO
B42: 0000230 | C42: F | D42: TOAV780815CP0 | E42: 780815 | F42: 12/09/2011 | G42: 08/12/2021 | H42: 17312.192 | I42: 147904.5 | J42: 51253.43 | K42: RECISION CONTRATO
B43: 0000246 | C43: M | D43: GORO620525U41 | E43: 620525 | F43: 01/02/2012 | G43: 08/12/2021 | H43: 7472.624 | I43: 69480.5 | J43: 22123.15 | K43: RECISION CONTRATO
B44: 0000276 | C44: F | D44: PART870610IL0 | E44: 870610 | F44: 25/06/2012 | G44: 08/12/2021 | H44: 18181.632 | I44: 138261.28 | J44: 53827.04 | K44: RENUNCIA VOLUNTARIA
B45: 0000290 | C45: F | D45: FUGE741115TQ6 | E45: 741115 | F45: 24/09/2012 | G45: 08/12/2021 | H45: 8231.104 | I45: 76101.11 | J45: 24368.49 | K45: RECISION CONTRATO
B46: 0000308 | C46: M | D46: BAJR890909I64 | E46: 890909 | F46: 16/01/2013 | G46: 08/12/2021 | H46: 12310.176 | I46: 91705.3 | J46: 36444.51 | K46: REESTRUCTURACION
B47: 0000372 | C47: M | D47: RATU811103EF8 | E47: 811103 | F47: 06/01/2014 | G47: 08/12/2021 | H47: 18156.704 | I47: 107422.28 | J47: 53753.59 | K47: RECISION CONTRATO
B48: 0000471 | C48: M | D48: NIGJ740922U38 | E48: 740922 | F48: 20/01/2015 | G48: 08/12/2021 | H48: 6879.52 | I48: 42664.16 | J48: 20367.27 | K48: RECISION CONTRATO
B49: 0000498 | C49: M | D49: MAMD891203IN3 | E49: 891203 | F49: 17/03/2015 | G49: 08/12/2021 | H49: 6785.888 | I49: 42082.78 | J49: 20089.72 | K49: REESTRUCTURACION
B50: 0000503 | C50: F | D50: CABJ720106A19 | E50: 720106 | F50: 07/04/2015 | G50: 08/12/2021 | H50: 8027.728 | I50: 49783.8 | J50: 23766.08 | K50: REESTRUCTURACION
...

Sheet Activos 2021
C1: Personal Activo al 31 de diciembre de 2021
B2: Núm. Nómina | C2: Número de Seguro Social (11 Dígitos) | D2: Sexo (M , F) | E2: RFC | F2: Fecha de Nacimiento (dd/mm/aaaa) | G2: Fecha de Ingreso Reconocida (dd/mm/aaaa) | H2: Salario integrado
B3: 0000002 | C3: 70886511255 | D3: M | E3: GUFF650507RE7 | F3: 650507 | G3: 04/02/1992 | H3: 198903.62
B4: 0000003 | C4: 45927277983 | D4: M | E4: ROMA7208057B3 | F4: 720805 | G4: 01/07/1992 | H4: 29646.688
B5: 0000004 | C5: 64866912112 | D5: M | E5: PAMN690418F47 | F5: 690418 | G5: 15/11/1992 | H5: 37349.44
B6: 0000005 | C6: 45947200825 | D6: F | E6: GAGS720516D59 | F6: 720516 | G6: 18/07/1994 | H6: 21341.408
B7: 0000007 | C7: 11886402442 | D7: F | E7: VIBG640904TE1 | F7: 640904 | G7: 28/11/1996 | H7: 23846.976
B8: 0000009 | C8: 28957509293 | D8: F | E8: VIRA750319CJ0 | F8: 750319 | G8: 04/05/1998 | H8: 97537.184
B9: 0000013 | C9: 01987103247 | D9: M | E9: GAVA711112CU4 | F9: 711112 | G9: 26/04/1999 | H9: 23375.168
B10: 0000018 | C10: 45996202714 | D10: F | E10: ROLA620912575 | F10: 620912 | G10: 01/11/1999 | H10: 83070.653
B11: 0000020 | C11: 76007400534 | D11: F | E11: PIMA740526PT6 | F11: 740526 | G11: 05/04/2000 | H11: 54104.704
B12: 0000026 | C12: 14926809337 | D12: M | E12: BAVJ6803186N3 | F12: 680318 | G12: 15/02/2001 | H12: 130428.16
B13: 0000032 | C13: 30947526080 | D13: F | E13: HESD751222DX4 | F13: 751222 | G13: 11/03/2002 | H13: 44115.872
B14: 0000033 | C14: 90917348667 | D14: F | E14: OEMF730618FR9 | F14: 730618 | G14: 11/03/2002 | H14: 31913.92
... B799: 0005724 | C799: 96119632337 | D799: M | E799: AASB960403NJ6 | F799: 960403 | G799: 07/12/2021 | H799: 23586.144
B800: 0000138 | C800: 88835906012 | D800: F | E800: HEEA590522219 | F800: 590522 | G800: 35856 | H800: 164973.82
B801: 0000881 | C801: 90047202099 | D801: M | E801: SALU720818UYA | F801: 720818 | G801: 02/01/2018 | H801: 165396.47
B802: 0001502 | C802: 39927339398 | D802: M | E802: AAPJ730716BK0 | F802: 730716 | G802: 01/06/2018 | H802: 225873.75
B803: 0001786 | C803: 07997502146 | D803: M | E803: LAUV750221TG4 | F803: 750221 | G803: 15/06/2017 | H803: 333034.38
B804: 0001788 | C804: 65917113709 | D804: F | E804: PORA710201KZ0 | F804: 710201 | G804: 02/08/2021 | H804: 132665.6
B805: 0002301 | C805: 45936714497 | D805: F | E805: CASA670424SD0 | F805: 670424 | G805: 16/10/1999 | H805: 37398.384
B806: 0002308 | C806: 94098721007 | D806: F | E806: AUBM8702271F2 | F806: 870227 | G806: 17/09/2009 | H806: 17815.92
B807: 0002314 | C807: 28098803191 | D807: F | E807: TOBM880102546 | F807: 880102 | G807: 16/01/2012 | H807: 17815.92
B808: 0002330 | C808: 30917212927 | D808: M | E808: PASA720805RS0 | F808: 720805 | G808: 01/08/2016 | H808: 47240.688
B809: 0002336 | C809: 45078816407 | D809: F | E809: CUGM880105NJ6 | F809: 880105 | G809: 18/10/2016 | H809: 23130.144
B810: 0002337 | C810: 45128902611 | D810: M | E810: AAGD890519SL2 | F810: 890519 | G810: 02/01/2017 | H810: 44843.04
B811: 0002338 | C811: 37967310519 | D811: M | E811: MAGM7303174T0 | F811: 730317 | G811: 20/01/2017 | H811: 19007.904
B812: 0002342 | C812: 10796045606 | D812: F | E812: PEGL600430B3A | F812: 600430 | G812: 10/05/2017 | H812: 16671.36
... B830: 0000593 | C830: 12977347751 | D830: M | E830: RORA760321A25 | F830: 760321 | G830: 15/12/2020 | H830: 69996.608

Sheet Bajas 2021
B2: Núm. Nómina | C2: Sexo (M , F) | D2: RFC | E2: Fecha de Nacimiento (dd/mm/aaaa) | F2: Fecha de Ingreso Reconocida (dd/mm/aaaa) | G2: Fecha de Baja (dd/mm/aaaa) | H2: Salario integrado | I2: Monto por Prima de Antigüedad | J2: Monto por Indemnización | K2: (*)Causa de Baja
B3: 489 | C3: M | D3: CABC751229N3A | E3: 751229 | F3: 42053 | G3: 44211 | H3: 6538.128 | I3: 12281.52 | J3: 36844.56 | K3: REESTRUCTURA
B4: 334 | C4: M | D4: JACR760709UW6 | E4: =MID(D4,5,6) -> 760709 | F4: 41415 | G4: 44211 | H4: 6474.592 | I4: 17027.19 | J4: 51081.57 | K4: REESTRUCTURA
B5: 501 | C5: M | D5: MESS6212106G3 | E5: =MID(D5,5,6) -> 621210 | F5: 42100 | G5: 44211 | H5: 6538.128 | I5: 12281.52 | J5: 36844.56 | K5: REESTRUCTURA
B6: 521 | C6: M | D6: MOVD681219CC3 | E6: =MID(D6,5,6) -> 681219 | F6: 42139 | G6: 44211 | H6: 6538.128 | I6: 12281.52 | J6: 36844.56 | K6: REESTRUCTURA
B7: 428 | C7: M | D7: RARF630827HM9 | E7: =MID(D7,5,6) -> 630827 | F7: 41842 | G7: 44211 | H7: 7011.76 | I7: 15805.72 | J7: 47417.16 | K7: REESTRUCTURA
B8: 251 | C8: M | D8: SACG760803LJ6 | E8: =MID(D8,5,6) -> 760803 | F8: 40974 | G8: 44211 | H8: 6644.224 | I8: 19969.8 | J8: 59909.4 | K8: REESTRUCTURA
B9: 229 | C9: M | D9: SACR780525SQ6 | E9: =MID(D9,5,6) -> 780525 | F9: 40798 | G9: 44211 | H9: 6952.48 | I9: 23477.2 | J9: 70431.6 | K9: REESTRUCTURA
B10: 1350 | C10: F | D10: COOM970731995 | E10: =MID(D10,5,6) -> 970731 | F10: 43349 | G10: 44221 | H10: 8702.912 | I10: 5824.53 | J10: 38944.16 | K10: REEMPLAZABLE
B11: 4806 | C11: M | D11: EICR800620HG1 | E11: =MID(D11,5,6) -> 800620 | F11: 44063 | G11: 44221 | H11: 8260.592 | I11: 0 | J11: 23845.09 | K11: REEMPLAZABLE
B12: 4723 | C12: M | D12: MALU900210IT7 | E12: =MID(D12,5,6) -> 900210 | F12: 44042 | G12: 44221 | H12: 8160.88 | I12: 0 | J12: 24145.56 | K12: REESTRUCTURA
B13: 809 | C13: M | D13: PISD9611261Z0 | E13: =MID(D13,5,6) -> 961126 | F13: 42916 | G13: 44221 | H13: 7547.712 | I13: 8377.48 | J13: 40183.11 | K13: REESTRUCTURA
B14: 783 | C14: F | D14: SADK8705034Y8 | E14: =MID(D14,5,6) -> 870503 | F14: 42884 | G14: 44221 | H14: 8871.024 | I14: 8689.7 | J14: 48783.17 | K14: REESTRUCTURA
B15: 629 | C15: M | D15: VAOA950203E45 | E15: =MID(D15,5,6) -> 950203 | F15: 42485 | G15: 44221 | H15: 10471.888 | I15: 13603.2 | J15: 59379.37 | K15: REESTRUCTURA
... B106: 5296 | C106: M | D106: MEVJ971222ML9 | E106: =MID(D106,5,6) -> 971222 | F106: 44343 | G106: 44496 | H106: 5776 | I106: 0 | J106: 15272.88 | K106: REEMPLAZABLE
B743: … | C743: … | D743: … | E743: … | F743: … | G743: … | H743: … | I743: … | J743: … | K743: …
B744: … | C744: … | D744: … | E744: … | F744: … | G744: … | H744: … | I744: … | J744: … | K744: …
B745: … | C745: … | D745: … | E745: … | F745: … | G745: … | H745: … | I745: … | J745: … | K745: …
B748: NOTAS IMPORTANTES:
B750: (*) CAUSA DE BAJA
B751: ROTACIÓN, SEPARACIÓN VOLUNTARIA, RECISIÓN DE CONTRATO, DESPIDO, FALLECIMIENTO, INVALIDEZ, CESANTÍA, JUBILACIÓN, ETC.
B752: REESTRUCTURACIÓN: Evento especial de derivado de un plan controlado por la entidad con el objeto de cambiar significativamente sus actividades o la manera de conducirlas (Ej: Cambios en la estructura de puestos ó cambios en el giro de la empresa).
A755: Nathal Actuarios y Consultores, S.A. de C.V.
A756: Insurgentes Sur 1796, 6° piso
A757: Col. Florida, 01030, Ciudad de México
A758: Tels.: 55-63-14-41, 55-63-17-46, 55-6315-36 Fax: 56-15-34-96
A759: www.nathalactuarios.com

Sheet Activos 2020
C1: Personal Activo al 31 de diciembre de 2020
B2: Núm. Nómina | C2: Número de Seguro Social (11 Dígitos) | D2: Sexo (M , F) | E2: RFC | F2: Fecha de Nacimiento (dd/mm/aaaa) | G2: Fecha de Ingreso Reconocida (dd/mm/aaaa) | H2: Salario integrado
B3: 0000002 | C3: 70886511255 | D3: M | E3: GUFF650507RE7 | F3: 650507 | G3: 04/02/1992 | H3: 102001.85
B4: 0000003 | C4: 45927277983 | D4: M | E4: ROMA7208057B3 | F4: 720805 | G4: 01/07/1992 | H4: 28471.424
B5: 0000004 | C5: 64866912112 | D5: M | E5: PAMN690418F47 | F5: 690418 | G5: 15/11/1992 | H5: 35868.352
B6: 0000005 | C6: 45947200825 | D6: F | E6: GAGS720516D59 | F6: 720516 | G6: 18/07/1994 | H6: 20520.608
B7: 0000007 | C7: 11886402442 | D7: F | E7: VIBG640904TE1 | F7: 640904 | G7: 28/11/1996 | H7: 22930.112
B8: 0000009 | C8: 28957509293 | D8: F | E8: VIRA750319CJ0 | F8: 750319 | G8: 04/05/1998 | H8: 67817.536
B9: 0000012 | C9: 01805814892 | D9: M | E9: CUMP580218JI6 | F9: 580218 | G9: 16/04/1999 | H9: 29732.416
B10: 0000013 | C10: 01987103247 | D10: M | E10: GAVA711112CU4 | F10: 711112 | G10: 26/04/1999 | H10: 26341.6
B11: 0000014 | C11: 42836217499 | D11: F | E11: MOAC621129LV6 | F11: 621129 | G11: 30/08/1999 | H11: 14131.136
B12: 0000018 | C12: 45996202714 | D12: F | E12: ROLA620912575 | F12: 620912 | G12: 01/11/1999 | H12: 58575.457
B13: 0000020 | C13: 76007400534 | D13: F | E13: PIMA740526PT6 | F13: 740526 | G13: 05/04/2000 | H13: 41618.816
B14: 0000024 | C14: 20816001067 | D14: F | E14: SEME601202799 | F14: 601202 | G14: 16/10/2000 | H14: 20493.248
... B835: 0005036 | C835: 12977347751 | D835: M | E835: RORA760321A25 | F835: 760321 | G835: 15/12/2020 | H835: 34951.488
B836: 0000138 | C836: 88835906012 | D836: F | E836: HEEA590522219 | F836: 590522 | G836: 35856 | H836: 80256.735
B837: 0000881 | C837: 90047202099 | D837: M | E837: SALU720818UYA | F837: 720818 | G837: 02/01/2018 | H837: 84818.695
B838: 0001502 | C838: 39927339398 | D838: M | E838: AAPJ730716BK0 | F838: 730716 | G838: 01/06/2018 | H838: 159269.95
B839: 0001679 | C839: 90897500451 | D839: M | E839: PARF750310RJ2 | F839: 750310 | G839: 15/01/2018 | H839: 83700.734
B840: 0001786 | C840: 07997502146 | D840: M | E840: LAUV750221TG4 | F840: 750221 | G840: 15/06/2017 | H840: 254663.05
B841: 0002301 | C841: 45936714497 | D841: F | E841: CASA670424SD0 | F841: 670424 | G841: 16/10/1999 | H841: 23973.44
B842: 0002308 | C842: 94098721007 | D842: F | E842: AUBM8702271F2 | F842: 870227 | G842: 17/09/2009 | H842: 11420.672
B843: 0002314 | C843: 28098803191 | D843: F | E843: TOBM880102546 | F843: 880102 | G843: 16/01/2012 | H843: 11405.472
B844: 0002319 | C844: 28047200713 | D844: M | E844: MOGA721128B56 | F844: 721128 | G844: 01/03/2014 | H844: 15101.504
B845: 0002330 | C845: 30917212927 | D845: M | E845: PASA720805RS0 | F845: 720805 | G845: 01/08/2016 | H845: 30282.656
B846: 0002333 | C846: 30977418794 | D846: F | E846: DOGC740802P31 | F846: 740802 | G846: 29/08/2016 | H846: 12304.096
B847: 0002336 | C847: 45078816407 | D847: F | E847: CUGM880105NJ6 | F847: 880105 | G847: 18/10/2016 | H847: 14826.688
B848: 0002337 | C848: 45128902611 | D848: M | E848: AAGD890519SL2 | F848: 890519 | G848: 02/01/2017 | H848: 28726.48
... B860: 0003038 | C860: 02189474584 | D860: F | E860: MERJ9408267QA | F860: 940826 | G860: 03/04/2018 | H860: 42972.224

Sheet 73 0 97
B2: Núm. Nómina | C2: Número de Seguro Social (11 Dígitos) | D2: Sexo (M , F) | E2: RFC | F2: Fecha de Nacimiento (dd/mm/aaaa) | G2: Fecha de Ingreso Reconocida (dd/mm/aaaa) | H2: Salario integrado | I2: AÑO DE INSCRIPCION AL SS | J2: REGIMEN DE PENSION
B3: 0000002 | C3: 70886511255 | D3: M | E3: GUFF650507RE7 | F3: 650507 | G3: 04/02/1992 | H3: 214815.92 | I3: =_xlfn.NUMBERVALUE(MID(C3,3,2)) -> 88 | J3: =IF(I3>25,IF(I3<=97,73,97),97) -> 73
B4: 0000003 | C4: 45927277983 | D4: M | E4: ROMA7208057B3 | F4: 720805 | G4: 01/07/1992 | H4: 16009.248 | I4: =_xlfn.NUMBERVALUE(MID(C4,3,2)) -> 92 | J4: =IF(I4>25,IF(I4<=97,73,97),97) -> 73
B5: 0000004 | C5: 64866912112 | D5: M | E5: PAMN690418F47 | F5: 690418 | G5: 15/11/1992 | H5: 20168.576 | I5: =_xlfn.NUMBERVALUE(MID(C5,3,2)) -> 86 | J5: =IF(I5>25,IF(I5<=97,73,97),97) -> 73
B6: 0000005 | C6: 45947200825 | D6: F | E6: GAGS720516D59 | F6: 720516 | G6: 18/07/1994 | H6: 11524.336 | I6: =_xlfn.NUMBERVALUE(MID(C6,3,2)) -> 94 | J6: =IF(I6>25,IF(I6<=97,73,97),97) -> 73
B7: 0000007 | C7: 11886402442 | D7: F | E7: VIBG640904TE1 | F7: 640904 | G7: 28/11/1996 | H7: 12877.44 | I7: =_xlfn.NUMBERVALUE(MID(C7,3,2)) -> 88 | J7: =IF(I7>25,IF(I7<=97,73,97),97) -> 73
B8: 0000009 | C8: 28957509293 | D8: F | E8: VIRA750319CJ0 | F8: 750319 | G8: 04/05/1998 | H8: 44069.36 | I8: =_xlfn.NUMBERVALUE(MID(C8,3,2)) -> 95 | J8: =IF(I8>25,IF(I8<=97,73,97),97) -> 73
B9: 0000013 | C9: 01987103247 | D9: M | E9: GAVA711112CU4 | F9: 711112 | G9: 26/04/1999 | H9: 17722.896 | I9: =_xlfn.NUMBERVALUE(MID(C9,3,2)) -> 98 | J9: =IF(I9>25,IF(I9<=97,73,97),97) -> 97
B10: 0000018 | C10: 45996202714 | D10: F | E10: ROLA620912575 | F10: 620912 | G10: 01/11/1999 | H10: 88054.895 | I10: =_xlfn.NUMBERVALUE(MID(C10,3,2)) -> 99 | J10: =IF(I10>25,IF(I10<=97,73,97),97) -> 97
B11: 0000020 | C11: 76007400534 | D11: F | E11: PIMA740526PT6 | F11: 740526 | G11: 05/04/2000 | H11: 29757.648 | I11: =_xlfn.NUMBERVALUE(MID(C11,3,2)) -> 0 | J11: =IF(I11>25,IF(I11<=97,73,97),97) -> 97
B12: 0000026 | C12: 14926809337 | D12: M | E12: BAVJ6803186N3 | F12: 680318 | G12: 15/02/2001 | H12: 56417.232 | I12: =_xlfn.NUMBERVALUE(MID(C12,3,2)) -> 92 | J12: =IF(I12>25,IF(I12<=97,73,97),97) -> 73
B13: 0000032 | C13: 30947526080 | D13: F | E13: HESD751222DX4 | F13: 751222 | G13: 11/03/2002 | H13: 24313.008 | I13: =_xlfn.NUMBERVALUE(MID(C13,3,2)) -> 94 | J13: =IF(I13>25,IF(I13<=97,73,97),97) -> 73
B14: 0000033 | C14: 90917348667 | D14: F | E14: OEMF730618FR9 | F14: 730618 | G14: 11/03/2002 | H14: 17233.456 | I14: =_xlfn.NUMBERVALUE(MID(C14,3,2)) -> 91 | J14: =IF(I14>25,IF(I14<=97,73,97),97) -> 73
... B886: 0006454 | C886: 96149956649 | D886: F | E886: RONL9909054I6 | F886: 990905 | G886: 03/10/2022 | H886: 6661.856 | I886: =_xlfn.NUMBERVALUE(MID(C886,3,2)) -> 14 | J886: =IF(I886>25,IF(I886<=97,73,97),97) -> 97
B887: 0000138 | C887: 88835906012 | D887: F | E887: HEEA590522219 | F887: 590522 | G887: 35856 | H887: 178171.72 | I887: =_xlfn.NUMBERVALUE(MID(C887,3,2)) -> 83 | J887: =IF(I887>25,IF(I887<=97,73,97),97) -> 73
B888: 0000881 | C888: 90047202099 | D888: M | E888: SALU720818UYA | F888: 720818 | G888: 02/01/2018 | H888: 178628.19 | I888: =_xlfn.NUMBERVALUE(MID(C888,3,2)) -> 4 | J888: =IF(I888>25,IF(I888<=97,73,97),97) -> 97
B889: 0001502 | C889: 39927339398 | D889: M | E889: AAPJ730716BK0 | F889: 730716 | G889: 01/06/2018 | H889: 243943.56 | I889: =_xlfn.NUMBERVALUE(MID(C889,3,2)) -> 92 | J889: =IF(I889>25,IF(I889<=97,73,97),97) -> 73
B890: 0001786 | C890: 07997502146 | D890: M | E890: LAUV750221TG4 | F890: 750221 | G890: 15/06/2017 | H890: 359677.27 | I890: =_xlfn.NUMBERVALUE(MID(C890,3,2)) -> 99 | J890: =IF(I890>25,IF(I890<=97,73,97),97) -> 97
B891: 0001788 | C891: 65917113709 | D891: F | E891: PORA710201KZ0 | F891: 710201 | G891: 02/08/2021 | H891: 143278.85 | I891: =_xlfn.NUMBERVALUE(MID(C891,3,2)) -> 91 | J891: =IF(I891>25,IF(I891<=97,73,97),97) -> 73
B892: 0001789 | C892: 64856408873 | D892: M | E892: PIGR640329Q61 | F892: 640329 | G892: 01/06/2017 | H892: 546673.14 | I892: =_xlfn.NUMBERVALUE(MID(C892,3,2)) -> 85 | J892: =IF(I892>25,IF(I892<=97,73,97),97) -> 73
B893: 0002301 | C893: 45936714497 | D893: F | E893: CASA670424SD0 | F893: 670424 | G893: 16/10/1999 | H893: 13463.248 | I893: =_xlfn.NUMBERVALUE(MID(C893,3,2)) -> 93 | J893: =IF(I893>25,IF(I893<=97,73,97),97) -> 73
B894: 0002308 | C894: 94098721007 | D894: F | E894: AUBM8702271F2 | F894: 870227 | G894: 17/09/2009 | H894: 6413.792 | I894: =_xlfn.NUMBERVALUE(MID(C894,3,2)) -> 9 | J894: =IF(I894>25,IF(I894<=97,73,97),97) -> 97
B895: 0002314 | C895: 28098803191 | D895: F | E895: TOBM880102546 | F895: 880102 | G895: 16/01/2012 | H895: 6413.792 | I895: =_xlfn.NUMBERVALUE(MID(C895,3,2)) -> 9 | J895: =IF(I895>25,IF(I895<=97,73,97),97) -> 97
B896: 0002330 | C896: 30917212927 | D896: M | E896: PASA720805RS0 | F896: 720805 | G896: 01/08/2016 | H896: 18014.736 | I896: =_xlfn.NUMBERVALUE(MID(C896,3,2)) -> 91 | J896: =IF(I896>25,IF(I896<=97,73,97),97) -> 73
B897: 0002336 | C897: 45078816407 | D897: F | E897: CUGM880105NJ6 | F897: 880105 | G897: 18/10/2016 | H897: 9307.568 | I897: =_xlfn.NUMBERVALUE(MID(C897,3,2)) -> 7 | J897: =IF(I897>25,IF(I897<=97,73,97),97) -> 97
B898: 0002337 | C898: 45128902611 | D898: M | E898: AAGD890519SL2 | F898: 890519 | G898: 02/01/2017 | H898: 16143.616 | I898: =_xlfn.NUMBERVALUE(MID(C898,3,2)) -> 12 | J898: =IF(I898>25,IF(I898<=97,73,97),97) -> 97
B899: 0002338 | C899: 37967310519 | D899: M | E899: MAGM7303174T0 | F899: 730317 | G899: 20/01/2017 | H899: 6843.04 | I899: =_xlfn.NUMBERVALUE(MID(C899,3,2)) -> 96 | J899: =IF(I899>25,IF(I899<=97,73,97),97) -> 73
... B916: 0000593 | C916: 12977347751 | D916: M | E916: RORA760321A25 | F916: 760321 | G916: 15/12/2020 | H916: 37798.144 | I916: =_xlfn.NUMBERVALUE(MID(C916,3,2)) -> 97 | J916: =IF(I916>25,IF(I916<=97,73,97),97) -> 73

Sheet 73
A1: Núm. Nómina | B1: Número de Seguro Social (11 Dígitos) | C1: Fecha de Nacimiento (dd/mm/aaaa) | D1: Fecha de nacimiento corregida | E1: Fecha de Ingreso Reconocida (dd/mm/aaaa) | F1: Salario integrado | G1: Año de Inscripción al IMSS | H1: Edad | I1: Años faltantes | J1: UMA Proyectada | K1: SI proyectado | L1: SBC | M1: SMG Proyectado | N1: Proporción | O1: Cuantía Básica | P1: Incremento Anual | Q1: Semanas cotizadas | R1: Pensión | S1: Tasa Reemplazo | T1: PROMEDIO DE TASA DE REEMPLAZO | U1: SI 2022 PROMEDIO
A2: 0000002 | B2: 70886511255 | C2: 650507 | D2: =_xlfn.CONCAT(MID(C2,5,2),"/",MID(C2,3,2),"/",MID(C2,1,2)) -> 07/05/65 | E2: 04/02/1992 | F2: 214815.92 | G2: =MID(B2,3,2) -> 88 | H2: =2022-YEAR(D2) -> 57 | I2: =65-H2 -> 8 | J2: =103.74*(1+0.04)^I2 -> 141.97535 | K2: =F2*(1+0.06)^I2 -> 342383.93 | L2: =MIN(K2,25*J2*30.4) -> 107901.27 | M2: =207.44*(1+0.05)^I2 -> 306.48336 | N2: =L2/(M2*30) -> 11.735414 | O2: =_xlfn.XLOOKUP(N2,CBIA!$A$3:$A$24,CBIA!$C$3:$C$24,,-1) -> 0.13 | P2: =_xlfn.XLOOKUP(N2,CBIA!$A$3:$A$24,CBIA!$D$3:$D$24,,-1) -> 0.0245 | Q2: =(122-G2+I2)*52 -> 2184 | R2: =L2*(O2+P2*((Q2-500)/52)) -> 99638.521 | S2: =R2/K2 -> 0.29101401 | T2: =AVERAGE(S2:S232) -> 0.9837812 | U2: =AVERAGE(F2:F232) -> 23134.755
A3: 0000003 | B3: 45927277983 | C3: 720805 | D3: =_xlfn.CONCAT(MID(C3,5,2),"/",MID(C3,3,2),"/",MID(C3,1,2)) -> 05/08/72 | E3: 01/07/1992 | F3: 16009.248 | G3: =MID(B3,3,2) -> 92 | H3: =2022-YEAR(D3) -> 50 | I3: =65-H3 -> 15 | J3: =103.74*(1+0.04)^I3 -> 186.82988 | K3: =F3*(1+0.06)^I3 -> 38367.094 | L3: =MIN(K3,25*J3*30.4) -> 38367.094 | M3: =207.44*(1+0.05)^I3 -> 431.25286 | N3: =L3/(M3*30) -> 2.9655528 | O3: =_xlfn.XLOOKUP(N3,CBIA!$A$3:$A$24,CBIA!$C$3:$C$24,,-1) -> 0.2783 | P3: =_xlfn.XLOOKUP(N3,CBIA!$A$3:$A$24,CBIA!$D$3:$D$24,,-1) -> 0.02033 | Q3: =(122-G3+I3)*52 -> 2340 | R3: =L3*(O3+P3*((Q3-500)/52)) -> 38277.67 | S3: =R3/K3 -> 0.99766923 | U3: =U2 -> 23134.755
A4: 0000004 | B4: 64866912112 | C4: 690418 | D4: =_xlfn.CONCAT(MID(C4,5,2),"/",MID(C4,3,2),"/",MID(C4,1,2)) -> 18/04/69 | E4: 15/11/1992 | F4: 20168.576 | G4: =MID(B4,3,2) -> 86 | H4: =2022-YEAR(D4) -> 53 | I4: =65-H4 -> 12 | J4: =103.74*(1+0.04)^I4 -> 166.09108 | K4: =F4*(1+0.06)^I4 -> 40583.137 | L4: =MIN(K4,25*J4*30.4) -> 40583.137 | M4: =207.44*(1+0.05)^I4 -> 372.53244 | N4: =L4/(M4*30) -> 3.6312845 | O4: =_xlfn.XLOOKUP(N4,CBIA!$A$3:$A$24,CBIA!$C$3:$C$24,,-1) -> 0.2207 | P4: =_xlfn.XLOOKUP(N4,CBIA!$A$3:$A$24,CBIA!$D$3:$D$24,,-1) -> 0.02195 | Q4: =(122-G4+I4)*52 -> 2496 | R4: =L4*(O4+P4*((Q4-500)/52)) -> 43149.709 | S4: =R4/K4 -> 1.0632423
A5: 0000005 | B5: 45947200825 | C5: 720516 | D5: =_xlfn.CONCAT(MID(C5,5,2),"/",MID(C5,3,2),"/",MID(C5,1,2)) -> 16/05/72 | E5: 18/07/1994 | F5: 11524.336 | G5: =MID(B5,3,2) -> 94 | H5: =2022-YEAR(D5) -> 50 | I5: =65-H5 -> 15 | J5: =103.74*(1+0.04)^I5 -> 186.82988 | K5: =F5*(1+0.06)^I5 -> 27618.742 | L5: =MIN(K5,25*J5*30.4) -> 27618.742 | M5: =207.44*(1+0.05)^I5 -> 431.25286 | N5: =L5/(M5*30) -> 2.1347678 | O5: =_xlfn.XLOOKUP(N5,CBIA!$A$3:$A$24,CBIA!$C$3:$C$24,,-1) -> 0.3765 | P5: =_xlfn.XLOOKUP(N5,CBIA!$A$3:$A$24,CBIA!$D$3:$D$24,,-1) -> 0.01756 | Q5: =(122-G5+I5)*52 -> 2236 | R5: =L5*(O5+P5*((Q5-500)/52)) -> 26589.498 | S5: =R5/K5 -> 0.96273385
A6: 0000007 | B6: 11886402442 | C6: 640904 | D6: =_xlfn.CONCAT(MID(C6,5,2),"/",MID(C6,3,2),"/",MID(C6,1,2)) -> 04/09/64 | E6: 28/11/1996 | F6: 12877.44 | G6: =MID(B6,3,2) -> 88 | H6: =2022-YEAR(D6) -> 58 | I6: =65-H6 -> 7 | J6: =103.74*(1+0.04)^I6 -> 136.51476 | K6: =F6*(1+0.06)^I6 -> 19362.908 | L6: =MIN(K6,25*J6*30.4) -> 19362.908 | M6: =207.44*(1+0.05)^I6 -> 291.88891 | N6: =L6/(M6*30) -> 2.2112189 | O6: =_xlfn.XLOOKUP(N6,CBIA!$A$3:$A$24,CBIA!$C$3:$C$24,,-1) -> 0.3765 | P6: =_xlfn.XLOOKUP(N6,CBIA!$A$3:$A$24,CBIA!$D$3:$D$24,,-1) -> 0.01756 | Q6: =(122-G6+I6)*52 -> 2132 | R6: =L6*(O6+P6*((Q6-500)/52)) -> 17961.302 | S6: =R6/K6 -> 0.92761385
A7: 0000009 | B7: 28957509293 | C7: 750319 | D7: =_xlfn.CONCAT(MID(C7,5,2),"/",MID(C7,3,2),"/",MID(C7,1,2)) -> 19/03/75 | E7: 04/05/1998 | F7: 44069.36 | G7: =MID(B7,3,2) -> 95 | H7: =2022-YEAR(D7) -> 47 | I7: =65-H7 -> 18 | J7: =103.74*(1+0.04)^I7 -> 210.15821 | K7: =F7*(1+0.06)^I7 -> 125788.9 | L7: =MIN(K7,25*J7*30.4) -> 125788.9 | M7: =207.44*(1+0.05)^I7 -> 499.22909 | N7: =L7/(M7*30) -> 8.3988761 | O7: =_xlfn.XLOOKUP(N7,CBIA!$A$3:$A$24,CBIA!$C$3:$C$24,,-1) -> 0.13 | P7: =_xlfn.XLOOKUP(N7,CBIA!$A$3:$A$24,CBIA!$D$3:$D$24,,-1) -> 0.0245 | Q7: =(122-G7+I7)*52 -> 2340 | R7: =L7*(O7+P7*((Q7-500)/52)) -> 125401.86 | S7: =R7/K7 -> 0.99692308
A8: 0000026 | B8: 14926809337 | C8: 680318 | D8: =_xlfn.CONCAT(MID(C8,5,2),"/",MID(C8,3,2),"/",MID(C8,1,2)) -> 18/03/68 | E8: 15/02/2001 | F8: 56417.232 | G8: =MID(B8,3,2) -> 92 | H8: =2022-YEAR(D8) -> 54 | I8: =65-H8 -> 11 | J8: =103.74*(1+0.04)^I8 -> 159.70296 | K8: =F8*(1+0.06)^I8 -> 107096.75 | L8: =MIN(K8,25*J8*30.4) -> 107096.75 | M8: =207.44*(1+0.05)^I8 -> 354.7928 | N8: =L8/(M8*30) -> 10.061906 | O8: =_xlfn.XLOOKUP(N8,CBIA!$A$3:$A$24,CBIA!$C$3:$C$24,,-1) -> 0.13 | P8: =_xlfn.XLOOKUP(N8,CBIA!$A$3:$A$24,CBIA!$D$3:$D$24,,-1) -> 0.0245 | Q8: =(122-G8+I8)*52 -> 2132 | R8: =L8*(O8+P8*((Q8-500)/52)) -> 96271.74 | S8: =R8/K8 -> 0.89892308
A9: 0000032 | B9: 30947526080 | C9: 751222 | D9: =_xlfn.CONCAT(MID(C9,5,2),"/",MID(C9,3,2),"/",MID(C9,1,2)) -> 22/12/75 | E9: 11/03/2002 | F9: 24313.008 | G9: =MID(B9,3,2) -> 94 | H9: =2022-YEAR(D9) -> 47 | I9: =65-H9 -> 18 | J9: =103.74*(1+0.04)^I9 -> 210.15821 | K9: =F9*(1+0.06)^I9 -> 69397.571 | L9: =MIN(K9,25*J9*30.4) -> 69397.571 | M9: =207.44*(1+0.05)^I9 -> 499.22909 | N9: =L9/(M9*30) -> 4.6336489 | O9: =_xlfn.XLOOKUP(N9,CBIA!$A$3:$A$24,CBIA!$C$3:$C$24,,-1) -> 0.173 | P9: =_xlfn.XLOOKUP(N9,CBIA!$A$3:$A$24,CBIA!$D$3:$D$24,,-1) -> 0.0233 | Q9: =(122-G9+I9)*52 -> 2392 | R9: =L9*(O9+P9*((Q9-500)/52)) -> 70838.371 | S9: =R9/K9 -> 1.0207615
A10: 0000033 | B10: 90917348667 | C10: 730618 | D10: =_xlfn.CONCAT(MID(C10,5,2),"/",MID(C10,3,2),"/",MID(C10,1,2)) -> 18/06/73 | E10: 11/03/2002 | F10: 17233.456 | G10: =MID(B10,3,2) -> 91 | H10: =2022-YEAR(D10) -> 49 | I10: =65-H10 -> 16 | J10: =103.74*(1+0.04)^I10 -> 194.30307 | K10: =F10*(1+0.06)^I10 -> 43779.039 | L10: =MIN(K10,25*J10*30.4) -> 43779.039 | M10: =207.44*(1+0.05)^I10 -> 452.8155 | N10: =L10/(M10*30) -> 3.2227282 | O10: =_xlfn.XLOOKUP(N10,CBIA!$A$3:$A$24,CBIA!$C$3:$C$24,,-1) -> 0.256 | P10: =_xlfn.XLOOKUP(N10,CBIA!$A$3:$A$24,CBIA!$D$3:$D$24,,-1) -> 0.02096 | Q10: =(122-G10+I10)*52 -> 2444 | R10: =L10*(O10+P10*((Q10-500)/52)) -> 45511.881 | S10: =R10/K10 -> 1.0395815
A11: 0000036 | B11: 20927038453 | C11: 701201 | D11: =_xlfn.CONCAT(MID(C11,5,2),"/",MID(C11,3,2),"/",MID(C11,1,2)) -> 01/12/70 | E11: 16/06/2002 | F11: 24767.792 | G11: =MID(B11,3,2) -> 92 | H11: =2022-YEAR(D11) -> 52 | I11: =65-H11 -> 13 | J11: =103.74*(1+0.04)^I11 -> 172.73473 | K11: =F11*(1+0.06)^I11 -> 52827.923 | L11: =MIN(K11,25*J11*30.4) -> 52827.923 | M11: =207.44*(1+0.05)^I11 -> 391.15906 | N11: =L11/(M11*30) -> 4.501828 | O11: =_xlfn.XLOOKUP(N11,CBIA!$A$3:$A$24,CBIA!$C$3:$C$24,,-1) -> 0.1829 | P11: =_xlfn.XLOOKUP(N11,CBIA!$A$3:$A$24,CBIA!$D$3:$D$24,,-1) -> 0.02302 | Q11: =(122-G11+I11)*52 -> 2236 | R11: =L11*(O11+P11*((Q11-500)/52)) -> 50261.218 | S11: =R11/K11 -> 0.95141385
A12: 0000037 | B12: 45977752059 | C12: 770816 | D12: =_xlfn.CONCAT(MID(C12,5,2),"/",MID(C12,3,2),"/",MID(C12,1,2)) -> 16/08/77 | E12: 17/07/2002 | F12: 16222.96 | G12: =MID(B12,3,2) -> 97 | H12: =2022-YEAR(D12) -> 45 | I12: =65-H12 -> 20 | J12: =103.74*(1+0.04)^I12 -> 227.30711 | K12: =F12*(1+0.06)^I12 -> 52029.23 | L12: =MIN(K12,25*J12*30.4) -> 52029.23 | M12: =207.44*(1+0.05)^I12 -> 550.40008 | N12: =L12/(M12*30) -> 3.1509946 | O12: =_xlfn.XLOOKUP(N12,CBIA!$A$3:$A$24,CBIA!$C$3:$C$24,,-1) -> 0.256 | P12: =_xlfn.XLOOKUP(N12,CBIA!$A$3:$A$24,CBIA!$D$3:$D$24,,-1) -> 0.02096 | Q12: =(122-G12+I12)*52 -> 2340 | R12: =L12*(O12+P12*((Q12-500)/52)) -> 51907.562 | S12: =R12/K12 -> 0.99766154
A13: 0000043 | B13: 45896927964 | C13: 690723 | D13: =_xlfn.CONCAT(MID(C13,5,2),"/",MID(C13,3,2),"/",MID(C13,1,2)) -> 23/07/69 | E13: 21/07/2003 | F13: 16808.464 | G13: =MID(B13,3,2) -> 89 | H13: =2022-YEAR(D13) -> 53 | I13: =65-H13 -> 12 | J13: =103.74*(1+0.04)^I13 -> 166.09108 | K13: =F13*(1+0.06)^I13 -> 33821.932 | L13: =MIN(K13,25*J13*30.4) -> 33821.932 | M13: =207.44*(1+0.05)^I13 -> 372.53244 | N13: =L13/(M13*30) -> 3.0263076 | O13: =_xlfn.XLOOKUP(N13,CBIA!$A$3:$A$24,CBIA!$C$3:$C$24,,-1) -> 0.256 | P13: =_xlfn.XLOOKUP(N13,CBIA!$A$3:$A$24,CBIA!$D$3:$D$24,,-1) -> 0.02096 | Q13: =(122-G13+I13)*52 -> 2340 | R13: =L13*(O13+P13*((Q13-500)/52)) -> 33742.841 | S13: =R13/K13 -> 0.99766154
A14: 0000045 | B14: 06795716668 | C14: 570618 | D14: =_xlfn.CONCAT(MID(C14,5,2),"/",MID(C14,3,2),"/",MID(C14,1,2)) -> 18/06/57 | E14: 07/08/2003 | F14: 7569.6 | G14: =MID(B14,3,2) -> 79 | H14: =2022-YEAR(D14) -> 65 | I14: =65-H14 -> 0 | J14: =103.74*(1+0.04)^I14 -> 103.74 | K14: =F14*(1+0.06)^I14 -> 7569.6 | L14: =MIN(K14,25*J14*30.4) -> 7569.6 | M14: =207.44*(1+0.05)^I14 -> 207.44 | N14: =L14/(M14*30) -> 1.2163517 | O14: =_xlfn.XLOOKUP(N14,CBIA!$A$3:$A$24,CBIA!$C$3:$C$24,,-1) -> 0.7711 | P14: =_xlfn.XLOOKUP(N14,CBIA!$A$3:$A$24,CBIA!$D$3:$D$24,,-1) -> 0.00814 | Q14: =(122-G14+I14)*52 -> 2236 | R14: =L14*(O14+P14*((Q14-500)/52)) -> 7893.9632 | S14: =R14/K14 -> 1.0428508
A15: 0000047 | B15: 11917326750 | C15: 730309 | D15: =_xlfn.CONCAT(MID(C15,5,2),"/",MID(C15,3,2),"/",MID(C15,1,2)) -> 09/03/73 | E15: 28/08/2003 | F15: 50655.52 | G15: =MID(B15,3,2) -> 91 | H15: =2022-YEAR(D15) -> 49 | I15: =65-H15 -> 16 | J15: =103.74*(1+0.04)^I15 -> 194.30307 | K15: =F15*(1+0.06)^I15 -> 128682.84 | L15: =MIN(K15,25*J15*30.4) -> 128682.84 | M15: =207.44*(1+0.05)^I15 -> 452.8155 | N15: =L15/(M15*30) -> 9.4727937 | O15: =_xlfn.XLOOKUP(N15,CBIA!$A$3:$A$24,CBIA!$C$3:$C$24,,-1) -> 0.13 | P15: =_xlfn.XLOOKUP(N15,CBIA!$A$3:$A$24,CBIA!$D$3:$D$24,,-1) -> 0.0245 | Q15: =(122-G15+I15)*52 -> 2444 | R15: =L15*(O15+P15*((Q15-500)/52)) -> 134592.35 | S15: =R15/K15 -> 1.0459231
... A216: 0006449 | B216: 92886713608 | C216: 670808 | D216: =_xlfn.CONCAT(MID(C216,5,2),"/",MID(C216,3,2),"/",MID(C216,1,2)) -> 08/08/67 | E216: 05/10/2022 | F216: 5602.72 | G216: =MID(B216,3,2) -> 88 | H216: =2022-YEAR(D216) -> 55 | I216: =65-H216 -> 10 | J216: =103.74*(1+0.04)^I216 -> 153.56054 | K216: =F216*(1+0.06)^I216 -> 10033.618 | L216: =MIN(K216,25*J216*30.4) -> 10033.618 | M216: =207.44*(1+0.05)^I216 -> 337.8979 | N216: =L216/(M216*30) -> 0.98980769 | O216: =_xlfn.XLOOKUP(N216,CBIA!$A$3:$A$24,CBIA!$C$3:$C$24,,-1) -> 0.8 | P216: =_xlfn.XLOOKUP(N216,CBIA!$A$3:$A$24,CBIA!$D$3:$D$24,,-1) -> 0.00563 | Q216: =(122-G216+I216)*52 -> 2288 | R216: =L216*(O216+P216*((Q216-500)/52)) -> 9969.2564 | S216: =R216/K216 -> 0.99358538
A217: 0000138 | B217: 88835906012 | C217: 590522 | D217: =_xlfn.CONCAT(MID(C217,5,2),"/",MID(C217,3,2),"/",MID(C217,1,2)) -> 22/05/59 | E217: 35856 | F217: 178171.72 | G217: =MID(B217,3,2) -> 83 | H217: =2022-YEAR(D217) -> 63 | I217: =65-H217 -> 2 | J217: =103.74*(1+0.04)^I217 -> 112.20518 | K217: =F217*(1+0.06)^I217 -> 200193.75 | L217: =MIN(K217,25*J217*30.4) -> 85275.94 | M217: =207.44*(1+0.05)^I217 -> 228.7026 | N217: =L217/(M217*30) -> 12.428942 | O217: =_xlfn.XLOOKUP(N217,CBIA!$A$3:$A$24,CBIA!$C$3:$C$24,,-1) -> 0.13 | P217: =_xlfn.XLOOKUP(N217,CBIA!$A$3:$A$24,CBIA!$D$3:$D$24,,-1) -> 0.0245 | Q217: =(122-G217+I217)*52 -> 2132 | R217: =L217*(O217+P217*((Q217-500)/52)) -> 76656.51 | S217: =R217/K217 -> 0.38291161
A218: 0001502 | B218: 39927339398 | C218: 730716 | D218: =_xlfn.CONCAT(MID(C218,5,2),"/",MID(C218,3,2),"/",MID(C218,1,2)) -> 16/07/73 | E218: 01/06/2018 | F218: 243943.56 | G218: =MID(B218,3,2) -> 92 | H218: =2022-YEAR(D218) -> 49 | I218: =65-H218 -> 16 | J218: =103.74*(1+0.04)^I218 -> 194.30307 | K218: =F218*(1+0.06)^I218 -> 619702.42 | L218: =MIN(K218,25*J218*30.4) -> 147670.34 | M218: =207.44*(1+0.05)^I218 -> 452.8155 | N218: =L218/(M218*30) -> 10.87053 | O218: =_xlfn.XLOOKUP(N218,CBIA!$A$3:$A$24,CBIA!$C$3:$C$24,,-1) -> 0.13 | P218: =_xlfn.XLOOKUP(N218,CBIA!$A$3:$A$24,CBIA!$D$3:$D$24,,-1) -> 0.0245 | Q218: =(122-G218+I218)*52 -> 2392 | R218: =L218*(O218+P218*((Q218-500)/52)) -> 150833.89 | S218: =R218/K218 -> 0.24339729
A219: 0001788 | B219: 65917113709 | C219: 710201 | D219: =_xlfn.CONCAT(MID(C219,5,2),"/",MID(C219,3,2),"/",MID(C219,1,2)) -> 01/02/71 | E219: 02/08/2021 | F219: 143278.85 | G219: =MID(B219,3,2) -> 91 | H219: =2022-YEAR(D219) -> 51 | I219: =65-H219 -> 14 | J219: =103.74*(1+0.04)^I219 -> 179.64411 | K219: =F219*(1+0.06)^I219 -> 323939.71 | L219: =MIN(K219,25*J219*30.4) -> 136529.53 | M219: =207.44*(1+0.05)^I219 -> 410.71701 | N219: =L219/(M219*30) -> 11.080584 | O219: =_xlfn.XLOOKUP(N219,CBIA!$A$3:$A$24,CBIA!$C$3:$C$24,,-1) -> 0.13 | P219: =_xlfn.XLOOKUP(N219,CBIA!$A$3:$A$24,CBIA!$D$3:$D$24,,-1) -> 0.0245 | Q219: =(122-G219+I219)*52 -> 2340 | R219: =L219*(O219+P219*((Q219-500)/52)) -> 136109.44 | S219: =R219/K219 -> 0.42016903
A220: 0001789 | B220: 64856408873 | C220: 640329 | D220: =_xlfn.CONCAT(MID(C220,5,2),"/",MID(C220,3,2),"/",MID(C220,1,2)) -> 29/03/64 | E220: 01/06/2017 | F220: 546673.14 | G220: =MID(B220,3,2) -> 85 | H220: =2022-YEAR(D220) -> 58 | I220: =65-H220 -> 7 | J220: =103.74*(1+0.04)^I220 -> 136.51476 | K220: =F220*(1+0.06)^I220 -> 821994.28 | L220: =MIN(K220,25*J220*30.4) -> 103751.22 | M220: =207.44*(1+0.05)^I220 -> 291.88891 | N220: =L220/(M220*30) -> 11.848254 | O220: =_xlfn.XLOOKUP(N220,CBIA!$A$3:$A$24,CBIA!$C$3:$C$24,,-1) -> 0.13 | P220: =_xlfn.XLOOKUP(N220,CBIA!$A$3:$A$24,CBIA!$D$3:$D$24,,-1) -> 0.0245 | Q220: =(122-G220+I220)*52 -> 2288 | R220: =L220*(O220+P220*((Q220-500)/52)) -> 100890.08 | S220: =R220/K220 -> 0.12273818
A221: 0002301 | B221: 45936714497 | C221: 670424 | D221: =_xlfn.CONCAT(MID(C221,5,2),"/",MID(C221,3,2),"/",MID(C221,1,2)) -> 24/04/67 | E221: 16/10/1999 | F221: 13463.248 | G221: =MID(B221,3,2) -> 93 | H221: =2022-YEAR(D221) -> 55 | I221: =65-H221 -> 10 | J221: =103.74*(1+0.04)^I221 -> 153.56054 | K221: =F221*(1+0.06)^I221 -> 24110.627 | L221: =MIN(K221,25*J221*30.4) -> 24110.627 | M221: =207.44*(1+0.05)^I221 -> 337.8979 | N221: =L221/(M221*30) -> 2.3784923 | O221: =_xlfn.XLOOKUP(N221,CBIA!$A$3:$A$24,CBIA!$C$3:$C$24,,-1) -> 0.3368 | P221: =_xlfn.XLOOKUP(N221,CBIA!$A$3:$A$24,CBIA!$D$3:$D$24,,-1) -> 0.01868 | Q221: =(122-G221+I221)*52 -> 2028 | R221: =L221*(O221+P221*((Q221-500)/52)) -> 21354.893 | S221: =R221/K221 -> 0.88570462
A222: 0002330 | B222: 30917212927 | C222: 720805 | D222: =_xlfn.CONCAT(MID(C222,5,2),"/",MID(C222,3,2),"/",MID(C222,1,2)) -> 05/08/72 | E222: 01/08/2016 | F222: 18014.736 | G222: =MID(B222,3,2) -> 91 | H222: =2022-YEAR(D222) -> 50 | I222: =65-H222 -> 15 | J222: =103.74*(1+0.04)^I222 -> 186.82988 | K222: =F222*(1+0.06)^I222 -> 43173.363 | L222: =MIN(K222,25*J222*30.4) -> 43173.363 | M222: =207.44*(1+0.05)^I222 -> 431.25286 | N222: =L222/(M222*30) -> 3.3370494 | O222: =_xlfn.XLOOKUP(N222,CBIA!$A$3:$A$24,CBIA!$C$3:$C$24,,-1) -> 0.237 | P222: =_xlfn.XLOOKUP(N222,CBIA!$A$3:$A$24,CBIA!$D$3:$D$24,,-1) -> 0.02149 | Q222: =(122-G222+I222)*52 -> 2392 | R222: =L222*(O222+P222*((Q222-500)/52)) -> 43989.572 | S222: =R222/K222 -> 1.0189054
A223: 0002338 | B223: 37967310519 | C223: 730317 | D223: =_xlfn.CONCAT(MID(C223,5,2),"/",MID(C223,3,2),"/",MID(C223,1,2)) -> 17/03/73 | E223: 20/01/2017 | F223: 6843.04 | G223: =MID(B223,3,2) -> 96 | H223: =2022-YEAR(D223) -> 49 | I223: =65-H223 -> 16 | J223: =103.74*(1+0.04)^I223 -> 194.30307 | K223: =F223*(1+0.06)^I223 -> 17383.728 | L223: =MIN(K223,25*J223*30.4) -> 17383.728 | M223: =207.44*(1+0.05)^I223 -> 452.8155 | N223: =L223/(M223*30) -> 1.279677 | O223: =_xlfn.XLOOKUP(N223,CBIA!$A$3:$A$24,CBIA!$C$3:$C$24,,-1) -> 0.5818 | P223: =_xlfn.XLOOKUP(N223,CBIA!$A$3:$A$24,CBIA!$D$3:$D$24,,-1) -> 0.01178 | Q223: =(122-G223+I223)*52 -> 2184 | R223: =L223*(O223+P223*((Q223-500)/52)) -> 16745.585 | S223: =R223/K223 -> 0.96329077
A224: 0002342 | B224: 10796045606 | C224: 600430 | D224: =_xlfn.CONCAT(MID(C224,5,2),"/",MID(C224,3,2),"/",MID(C224,1,2)) -> 30/04/60 | E224: 10/05/2017 | F224: 5632.208 | G224: =MID(B224,3,2) -> 79 | H224: =2022-YEAR(D224) -> 62 | I224: =65-H224 -> 3 | J224: =103.74*(1+0.04)^I224 -> 116.69339 | K224: =F224*(1+0.06)^I224 -> 6708.0498 | L224: =MIN(K224,25*J224*30.4) -> 6708.0498 | M224: =207.44*(1+0.05)^I224 -> 240.13773 | N224: =L224/(M224*30) -> 0.93113923 | O224: =_xlfn.XLOOKUP(N224,CBIA!$A$3:$A$24,CBIA!$C$3:$C$24,,-1) -> 0.8 | P224: =_xlfn.XLOOKUP(N224,CBIA!$A$3:$A$24,CBIA!$D$3:$D$24,,-1) -> 0.00563 | Q224: =(122-G224+I224)*52 -> 2392 | R224: =L224*(O224+P224*((Q224-500)/52)) -> 6740.5529 | S224: =R224/K224 -> 1.0048454
A225: 0002347 | B225: 10826341330 | C225: 630425 | D225: =_xlfn.CONCAT(MID(C225,5,2),"/",MID(C225,3,2),"/",MID(C225,1,2)) -> 25/04/63 | E225: 05/06/2017 | F225: 5632.208 | G225: =MID(B225,3,2) -> 82 | H225: =2022-YEAR(D225) -> 59 | I225: =65-H225 -> 6 | J225: =103.74*(1+0.04)^I225 -> 131.26419 | K225: =F225*(1+0.06)^I225 -> 7989.3947 | L225: =MIN(K225,25*J225*30.4) -> 7989.3947 | M225: =207.44*(1+0.05)^I225 -> 277.98944 | N225: =L225/(M225*30) -> 0.95799739 | O225: =_xlfn.XLOOKUP(N225,CBIA!$A$3:$A$24,CBIA!$C$3:$C$24,,-1) -> 0.8 | P225: =_xlfn.XLOOKUP(N225,CBIA!$A$3:$A$24,CBIA!$D$3:$D$24,,-1) -> 0.00563 | Q225: =(122-G225+I225)*52 -> 2392 | R225: =L225*(O225+P225*((Q225-500)/52)) -> 8028.1064 | S225: =R225/K225 -> 1.0048454
A226: 0002357 | B226: 65886842825 | C226: 680728 | D226: =_xlfn.CONCAT(MID(C226,5,2),"/",MID(C226,3,2),"/",MID(C226,1,2)) -> 28/07/68 | E226: 19/09/2017 | F226: 5632.208 | G226: =MID(B226,3,2) -> 88 | H226: =2022-YEAR(D226) -> 54 | I226: =65-H226 -> 11 | J226: =103.74*(1+0.04)^I226 -> 159.70296 | K226: =F226*(1+0.06)^I226 -> 10691.612 | L226: =MIN(K226,25*J226*30.4) -> 10691.612 | M226: =207.44*(1+0.05)^I226 -> 354.7928 | N226: =L226/(M226*30) -> 1.0044936 | O226: =_xlfn.XLOOKUP(N226,CBIA!$A$3:$A$24,CBIA!$C$3:$C$24,,-1) -> 0.8 | P226: =_xlfn.XLOOKUP(N226,CBIA!$A$3:$A$24,CBIA!$D$3:$D$24,,-1) -> 0.00563 | Q226: =(122-G226+I226)*52 -> 2340 | R226: =L226*(O226+P226*((Q226-500)/52)) -> 10683.224 | S226: =R226/K226 -> 0.99921538
A227: 0003035 | B227: 01917314765 | C227: 740506 | D227: =_xlfn.CONCAT(MID(C227,5,2),"/",MID(C227,3,2),"/",MID(C227,1,2)) -> 06/05/74 | E227: 24/06/2019 | F227: 17069.904 | G227: =MID(B227,3,2) -> 91 | H227: =2022-YEAR(D227) -> 48 | I227: =65-H227 -> 17 | J227: =103.74*(1+0.04)^I227 -> 202.0752 | K227: =F227*(1+0.06)^I227 -> 45965.373 | L227: =MIN(K227,25*J227*30.4) -> 45965.373 | M227: =207.44*(1+0.05)^I227 -> 475.45628 | N227: =L227/(M227*30) -> 3.2225447 | O227: =_xlfn.XLOOKUP(N227,CBIA!$A$3:$A$24,CBIA!$C$3:$C$24,,-1) -> 0.256 | P227: =_xlfn.XLOOKUP(N227,CBIA!$A$3:$A$24,CBIA!$D$3:$D$24,,-1) -> 0.02096 | Q227: =(122-G227+I227)*52 -> 2496 | R227: =L227*(O227+P227*((Q227-500)/52)) -> 48748.187 | S227: =R227/K227 -> 1.0605415
A228: 0001904 | B228: 39957427550 | C228: 740703 | D228: =_xlfn.CONCAT(MID(C228,5,2),"/",MID(C228,3,2),"/",MID(C228,1,2)) -> 03/07/74 | E228: 22/01/2008 | F228: 32364.144 | G228: =MID(B228,3,2) -> 95 | H228: =2022-YEAR(D228) -> 48 | I228: =65-H228 -> 17 | J228: =103.74*(1+0.04)^I228 -> 202.0752 | K228: =F228*(1+0.06)^I228 -> 87149.286 | L228: =MIN(K228,25*J228*30.4) -> 87149.286 | M228: =207.44*(1+0.05)^I228 -> 475.45628 | N228: =L228/(M228*30) -> 6.1098703 | O228: =_xlfn.XLOOKUP(N228,CBIA!$A$3:$A$24,CBIA!$C$3:$C$24,,-1) -> 0.13 | P228: =_xlfn.XLOOKUP(N228,CBIA!$A$3:$A$24,CBIA!$D$3:$D$24,,-1) -> 0.0245 | Q228: =(122-G228+I228)*52 -> 2288 | R228: =L228*(O228+P228*((Q228-500)/52)) -> 84745.977 | S228: =R228/K228 -> 0.97242308
A229: 0000020 | B229: 45927023247 | C229: 701103 | D229: =_xlfn.CONCAT(MID(C229,5,2),"/",MID(C229,3,2),"/",MID(C229,1,2)) -> 03/11/70 | E229: 16/09/2003 | F229: 50243.6 | G229: =MID(B229,3,2) -> 92 | H229: =2022-YEAR(D229) -> 52 | I229: =65-H229 -> 13 | J229: =103.74*(1+0.04)^I229 -> 172.73473 | K229: =F229*(1+0.06)^I229 -> 107165.99 | L229: =MIN(K229,25*J229*30.4) -> 107165.99 | M229: =207.44*(1+0.05)^I229 -> 391.15906 | N229: =L229/(M229*30) -> 9.1323459 | O229: =_xlfn.XLOOKUP(N229,CBIA!$A$3:$A$24,CBIA!$C$3:$C$24,,-1) -> 0.13 | P229: =_xlfn.XLOOKUP(N229,CBIA!$A$3:$A$24,CBIA!$D$3:$D$24,,-1) -> 0.0245 | Q229: =(122-G229+I229)*52 -> 2236 | R229: =L229*(O229+P229*((Q229-500)/52)) -> 101585.12 | S229: =R229/K229 -> 0.94792308
... A232: 0000593 | B232: 12977347751 | C232: 760321 | D232: =_xlfn.CONCAT(MID(C232,5,2),"/",MID(C232,3,2),"/",MID(C232,1,2)) -> 21/03/76 | E232: 15/12/2020 | F232: 37798.144 | G232: =MID(B232,3,2) -> 97 | H232: =2022-YEAR(D232) -> 46 | I232: =65-H232 -> 19 | J232: =103.74*(1+0.04)^I232 -> 218.56453 | K232: =F232*(1+0.06)^I232 -> 114362.05 | L232: =MIN(K232,25*J232*30.4) -> 114362.05 | M232: =207.44*(1+0.05)^I232 -> 524.19055 | N232: =L232/(M232*30) -> 7.2722948 | O232: =_xlfn.XLOOKUP(N232,CBIA!$A$3:$A$24,CBIA!$C$3:$C$24,,-1) -> 0.13 | P232: =_xlfn.XLOOKUP(N232,CBIA!$A$3:$A$24,CBIA!$D$3:$D$24,,-1) -> 0.0245 | Q232: =(122-G232+I232)*52 -> 2288 | R232: =L232*(O232+P232*((Q232-500)/52)) -> 111208.29 | S232: =R232/K232 -> 0.97242308
F233: =F232 -> 37798.144 | G233: 96 | H233: 51 | I233: 14 | J233: =103.74*(1+0.04)^I233 -> 179.64411 | K233: =F233*(1+0.06)^I233 -> 85457.973 | L233: =MIN(K233,25*J233*30.4) -> 85457.973 | M233: =207.44*(1+0.05)^I233 -> 410.71701 | N233: =L233/(M233*30) -> 6.9356736 | O233: =_xlfn.XLOOKUP(N233,CBIA!$A$3:$A$24,CBIA!$C$3:$C$24,,-1) -> 0.13 | P233: =_xlfn.XLOOKUP(N233,CBIA!$A$3:$A$24,CBIA!$D$3:$D$24,,-1) -> 0.0245 | Q233: =(122-G233+I233)*52 -> 2080 | R233: =L233*(O233+P233*((Q233-500)/52)) -> 74726.424 | S233: =R233/K233 -> 0.87442308
K234: 85457.97 | R234: 74726.424

Sheet CBIA
A2: Límite inf | B2: Límite Sup | C2: Cuantía | D2: Incremento Anual
A3: 0 | B3: 1 | C3: 0.8 | D3: 0.00563
A4: 1.01 | B4: 1.25 | C4: 0.7711 | D4: 0.00814
A5: 1.26 | B5: 1.5 | C5: 0.5818 | D5: 0.01178
A6: 1.51 | B6: 1.75 | C6: 0.4923 | D6: 0.0143
A7: 1.76 | B7: 2 | C7: 0.4267 | D7: 0.01615
A8: 2.01 | B8: 2.25 | C8: 0.3765 | D8: 0.01756
A9: 2.26 | B9: 2.5 | C9: 0.3368 | D9: 0.01868
A10: 2.51 | B10: 2.75 | C10: 0.3048 | D10: 0.01958
A11: 2.76 | B11: 3 | C11: 0.2783 | D11: 0.02033
A12: 3.01 | B12: 3.25 | C12: 0.256 | D12: 0.02096
A13: 3.26 | B13: 3.5 | C13: 0.237 | D13: 0.02149
A14: 3.51 | B14: 3.75 | C14: 0.2207 | D14: 0.02195
... A23: 5.76 | B23: 6 | C23: 0.1362 | D23: 0.02433
A24: 6.01 | C24: 0.13 | D24: 0.0245

Sheet 97
A1: Núm. Nómina | B1: Número de Seguro Social (11 Dígitos) | C1: Fecha de Nacimiento (dd/mm/aaaa) | D1: Fecha de Nacimiento Corregida (dd/mm/aaaa) | E1: Fecha de Ingreso Reconocida (dd/mm/aaaa) | F1: Salario integrado | G1: SI corregido | H1: Año de Inscripción al IMSS | I1: Edad | J1: Antigüedad | K1: Años faltantes | L1: Años cotizados (2022) | M1: Total de años cotizados | N1: Salario inicial | O1: Monto acumulado a edad de retiro S | P1: AFORE a edad de retiro | Q1: Pensión mensual | R1: SI a edad de retiro | S1: Tasa de reemplazo | T1: PROMEDIO TASA DE REEMPLAZO
A2: 0000013 | B2: 01987103247 | C2: 711112 | D2: =_xlfn.CONCAT(MID(C2,5,2),"/",MID(C2,3,2),"/",MID(C2,1,2)) -> 12/11/71 | E2: 26/04/1999 | F2: 17722.896 | G2: =IF(F2=0,$Y$3,F2) -> 17722.896 | H2: =_xlfn.NUMBERVALUE(MID(B2,3,2)) -> 98 | I2: =2022-YEAR(D2) -> 51 | J2: =2022-YEAR(E2) -> 23 | K2: =65-I2 -> 14 | L2: =IF(H2>22,122-H2,22-H2) -> 24 | M2: =L2+K2 -> 38 | N2: =G2*(1+0.06)^-J2 -> 4639.8056 | O2: =((1-((1+$W$11)/(1+$W$10))^(6*(J2+K2)))/($W$10-$W$11))*(1+$W$10)^(6*(J2+K2)) -> 2268.4845 | P2: =N2*0.065*O2 -> 684146.27 | Q2: =P2/150 -> 4560.9751 | R2: =G2*(1+0.06)^K2 -> 40069.766 | S2: =Q2/R2 -> 0.11382585 | T2: =AVERAGE(S2:S684) -> 0.105092 | V2: UMA 2022 | W2: 103.74 | X2: PROMEDIO SI 2022 | Y2: =AVERAGE(F2:F684) -> 15640.205
A3: 0000018 | B3: 45996202714 | C3: 620912 | D3: =_xlfn.CONCAT(MID(C3,5,2),"/",MID(C3,3,2),"/",MID(C3,1,2)) -> 12/09/62 | E3: 01/11/1999 | F3: 88054.895 | G3: =IF(F3=0,$Y$3,F3) -> 88054.895 | H3: =_xlfn.NUMBERVALUE(MID(B3,3,2)) -> 99 | I3: =2022-YEAR(D3) -> 60 | J3: =2022-YEAR(E3) -> 23 | K3: =65-I3 -> 5 | L3: =IF(H3>22,122-H3,22-H3) -> 23 | M3: =L3+K3 -> 28 | N3: =G3*(1+0.06)^-J3 -> 23052.53 | O3: =(((1-((1+$W$11)/(1+$W$10))^(6*(J3+K3)))/($W$10-$W$11))*(1+$W$10)^(6*(J3+K3))) -> 971.97898 | P3: =N3*0.065*O3 -> 1456427.4 | Q3: =P3/150 -> 9709.5158 | R3: =G3*(1+0.06)^K3 -> 117837.31 | S3: =Q3/R3 -> 0.082397634 | V3: Inc salarial | W3: 0.06 | Y3: 15640.21
A4: 0000020 | B4: 76007400534 | C4: 740526 | D4: =_xlfn.CONCAT(MID(C4,5,2),"/",MID(C4,3,2),"/",MID(C4,1,2)) -> 26/05/74 | E4: 05/04/2000 | F4: 29757.648 | G4: =IF(F4=0,$Y$3,F4) -> 29757.648 | H4: =_xlfn.NUMBERVALUE(MID(B4,3,2)) -> 0 | I4: =2022-YEAR(D4) -> 48 | J4: =2022-YEAR(E4) -> 22 | K4: =65-I4 -> 17 | L4: =IF(H4>22,122-H4,22-H4) -> 22 | M4: =L4+K4 -> 39 | N4: =G4*(1+0.06)^-J4 -> 8257.899 | O4: =(((1-((1+$W$11)/(1+$W$10))^(6*(J4+K4)))/($W$10-$W$11))*(1+$W$10)^(6*(J4+K4))) -> 2713.5032 | P4: =N4*0.065*O4 -> 1456509.3 | Q4: =P4/150 -> 9710.062 | R4: =G4*(1+0.06)^K4 -> 80130.585 | S4: =Q4/R4 -> 0.12117797 | V4: i | W4: 0.07
A5: 0000042 | B5: 45016702503 | C5: 670903 | D5: =_xlfn.CONCAT(MID(C5,5,2),"/",MID(C5,3,2),"/",MID(C5,1,2)) -> 03/09/67 | E5: 03/07/2003 | F5: 10638.48 | G5: =IF(F5=0,$Y$3,F5) -> 10638.48 | H5: =_xlfn.NUMBERVALUE(MID(B5,3,2)) -> 1 | I5: =2022-YEAR(D5) -> 55 | J5: =2022-YEAR(E5) -> 19 | K5: =65-I5 -> 10 | L5: =IF(H5>22,122-H5,22-H5) -> 21 | M5: =L5+K5 -> 31 | N5: =G5*(1+0.06)^-J5 -> 3516.1561 | O5: =(((1-((1+$W$11)/(1+$W$10))^(6*(J5+K5)))/($W$10-$W$11))*(1+$W$10)^(6*(J5+K5))) -> 1072.34 | P5: =N5*0.065*O5 -> 245083.45 | Q5: =P5/150 -> 1633.8897 | R5: =G5*(1+0.06)^K5 -> 19051.897 | S5: =Q5/R5 -> 0.085759946 | V5: Inflación | W5: 0.04
A6: 0000052 | B6: 39998016990 | C6: 800801 | D6: =_xlfn.CONCAT(MID(C6,5,2),"/",MID(C6,3,2),"/",MID(C6,1,2)) -> 01/08/80 | E6: 18/09/2003 | F6: 36482.432 | G6: =IF(F6=0,$Y$3,F6) -> 36482.432 | H6: =_xlfn.NUMBERVALUE(MID(B6,3,2)) -> 99 | I6: =2022-YEAR(D6) -> 42 | J6: =2022-YEAR(E6) -> 19 | K6: =65-I6 -> 23 | L6: =IF(H6>22,122-H6,22-H6) -> 23 | M6: =L6+K6 -> 46 | N6: =G6*(1+0.06)^-J6 -> 12057.918 | O6: =(((1-((1+$W$11)/(1+$W$10))^(6*(J6+K6)))/($W$10-$W$11))*(1+$W$10)^(6*(J6+K6))) -> 3532.9399 | P6: =N6*0.065*O6 -> 2768993.5 | Q6: =P6/150 -> 18459.957 | R6: =G6*(1+0.06)^K6 -> 139353.76 | S6: =Q6/R6 -> 0.13246831 | V6: SMG 2022 | W6: 207.44
A7: 0000059 | B7: 45996804048 | C7: 681209 | D7: =_xlfn.CONCAT(MID(C7,5,2),"/",MID(C7,3,2),"/",MID(C7,1,2)) -> 09/12/68 | E7: 22/11/2004 | F7: 68321.568 | G7: =IF(F7=0,$Y$3,F7) -> 68321.568 | H7: =_xlfn.NUMBERVALUE(MID(B7,3,2)) -> 99 | I7: =2022-YEAR(D7) -> 54 | J7: =2022-YEAR(E7) -> 18 | K7: =65-I7 -> 11 | L7: =IF(H7>22,122-H7,22-H7) -> 23 | M7: =L7+K7 -> 34 | N7: =G7*(1+0.06)^-J7 -> 23936.037 | O7: =(((1-((1+$W$11)/(1+$W$10))^(6*(J7+K7)))/($W$10-$W$11))*(1+$W$10)^(6*(J7+K7))) -> 1072.34 | P7: =N7*0.065*O7 -> 1668392 | Q7: =P7/150 -> 11122.613 | R7: =G7*(1+0.06)^K7 -> 129694.73 | S7: =Q7/R7 -> 0.085759946 | V7: SMG 2022 mensual | W7: =W6*30.4 -> 6306.176
A8: 0000065 | B8: 20015900853 | C8: 590727 | D8: =_xlfn.CONCAT(MID(C8,5,2),"/",MID(C8,3,2),"/",MID(C8,1,2)) -> 27/07/59 | E8: 16/03/2005 | F8: 98035.247 | G8: =IF(F8=0,$Y$3,F8) -> 98035.247 | H8: =_xlfn.NUMBERVALUE(MID(B8,3,2)) -> 1 | I8: =2022-YEAR(D8) -> 63 | J8: =2022-YEAR(E8) -> 17 | K8: =65-I8 -> 2 | L8: =IF(H8>22,122-H8,22-H8) -> 21 | M8: =L8+K8 -> 23 | N8: =G8*(1+0.06)^-J8 -> 36406.802 | O8: =(((1-((1+$W$11)/(1+$W$10))^(6*(J8+K8)))/($W$10-$W$11))*(1+$W$10)^(6*(J8+K8))) -> 373.6584 | P8: =N8*0.065*O8 -> 884240.98 | Q8: =P8/150 -> 5894.9399 | R8: =G8*(1+0.06)^K8 -> 110152.4 | S8: =Q8/R8 -> 0.053516217 | V8: i(6) | W8: =6*((1+W4)^(1/6)-1) -> 0.068041561
A9: 0000067 | B9: 01058202746 | C9: 820126 | D9: =_xlfn.CONCAT(MID(C9,5,2),"/",MID(C9,3,2),"/",MID(C9,1,2)) -> 26/01/82 | E9: 06/04/2005 | F9: 69430.256 | G9: =IF(F9=0,$Y$3,F9) -> 69430.256 | H9: =_xlfn.NUMBERVALUE(MID(B9,3,2)) -> 5 | I9: =2022-YEAR(D9) -> 40 | J9: =2022-YEAR(E9) -> 17 | K9: =65-I9 -> 25 | L9: =IF(H9>22,122-H9,22-H9) -> 17 | M9: =L9+K9 -> 42 | N9: =G9*(1+0.06)^-J9 -> 25783.927 | O9: =(((1-((1+$W$11)/(1+$W$10))^(6*(J9+K9)))/($W$10-$W$11))*(1+$W$10)^(6*(J9+K9))) -> 3532.9399 | P9: =N9*0.065*O9 -> 5921049 | Q9: =P9/150 -> 39473.66 | R9: =G9*(1+0.06)^K9 -> 297985.68 | S9: =Q9/R9 -> 0.13246831 | V9: j(6) | W9: =6*((1+W3)^(1/6)-1) -> 0.058552765
A10: 0000072 | B10: 45006201615 | C10: 621028 | D10: =_xlfn.CONCAT(MID(C10,5,2),"/",MID(C10,3,2),"/",MID(C10,1,2)) -> 28/10/62 | E10: 10/01/2022 | F10: 22029.968 | G10: =IF(F10=0,$Y$3,F10) -> 22029.968 | H10: =_xlfn.NUMBERVALUE(MID(B10,3,2)) -> 0 | I10: =2022-YEAR(D10) -> 60 | J10: =2022-YEAR(E10) -> 0 | K10: =65-I10 -> 5 | L10: =IF(H10>22,122-H10,22-H10) -> 22 | M10: =L10+K10 -> 27 | N10: =G10*(1+0.06)^-J10 -> 22029.968 | O10: =(((1-((1+$W$11)/(1+$W$10))^(6*(J10+K10)))/($W$10-$W$11))*(1+$W$10)^(6*(J10+K10))) -> 40.675016 | P10: =N10*0.065*O10 -> 58244.505 | Q10: =P10/150 -> 388.2967 | R10: =G10*(1+0.06)^K10 -> 29481.067 | S10: =Q10/R10 -> 0.013171053 | V10: i(6)/6 | W10: =W8/6 -> 0.01134026
A11: 0000081 | B11: 30047100224 | C11: 710522 | D11: =_xlfn.CONCAT(MID(C11,5,2),"/",MID(C11,3,2),"/",MID(C11,1,2)) -> 22/05/71 | E11: 31/05/2006 | F11: 34279.952 | G11: =IF(F11=0,$Y$3,F11) -> 34279.952 | H11: =_xlfn.NUMBERVALUE(MID(B11,3,2)) -> 4 | I11: =2022-YEAR(D11) -> 51 | J11: =2022-YEAR(E11) -> 16 | K11: =65-I11 -> 14 | L11: =IF(H11>22,122-H11,22-H11) -> 18 | M11: =L11+K11 -> 32 | N11: =G11*(1+0.06)^-J11 -> 13494.176 | O11: =(((1-((1+$W$11)/(1+$W$10))^(6*(J11+K11)))/($W$10-$W$11))*(1+$W$10)^(6*(J11+K11))) -> 1181.6656 | P11: =N11*0.065*O11 -> 1036464.2 | Q11: =P11/150 -> 6909.7612 | R11: =G11*(1+0.06)^K11 -> 77503.679 | S11: =Q11/R11 -> 0.089153977 | V11: j(6)/6 | W11: =W9/6 -> 0.0097587942
A12: 0000082 | B12: 12048005875 | C12: 800623 | D12: =_xlfn.CONCAT(MID(C12,5,2),"/",MID(C12,3,2),"/",MID(C12,1,2)) -> 23/06/80 | E12: 01/06/2006 | F12: 16053.936 | G12: =IF(F12=0,$Y$3,F12) -> 16053.936 | H12: =_xlfn.NUMBERVALUE(MID(B12,3,2)) -> 4 | I12: =2022-YEAR(D12) -> 42 | J12: =2022-YEAR(E12) -> 16 | K12: =65-I12 -> 23 | L12: =IF(H12>22,122-H12,22-H12) -> 18 | M12: =L12+K12 -> 41 | N12: =G12*(1+0.06)^-J12 -> 6319.5722 | O12: =(((1-((1+$W$11)/(1+$W$10))^(6*(J12+K12)))/($W$10-$W$11))*(1+$W$10)^(6*(J12+K12))) -> 2713.5032 | P12: =N12*0.065*O12 -> 1114631.7 | Q12: =P12/150 -> 7430.8778 | R12: =G12*(1+0.06)^K12 -> 61322.017 | S12: =Q12/R12 -> 0.12117797 | V12: Anualidad | W12: 150
A13: 0000083 | B13: 45068413702 | C13: 840519 | D13: =_xlfn.CONCAT(MID(C13,5,2),"/",MID(C13,3,2),"/",MID(C13,1,2)) -> 19/05/84 | E13: 12/06/2006 | F13: 13900.4 | G13: =IF(F13=0,$Y$3,F13) -> 13900.4 | H13: =_xlfn.NUMBERVALUE(MID(B13,3,2)) -> 6 | I13: =2022-YEAR(D13) -> 38 | J13: =2022-YEAR(E13) -> 16 | K13: =65-I13 -> 27 | L13: =IF(H13>22,122-H13,22-H13) -> 16 | M13: =L13+K13 -> 43 | N13: =G13*(1+0.06)^-J13 -> 5471.8408 | O13: =(((1-((1+$W$11)/(1+$W$10))^(6*(J13+K13)))/($W$10-$W$11))*(1+$W$10)^(6*(J13+K13))) -> 3853.3236 | P13: =N13*0.065*O13 -> 1370510.3 | Q13: =P13/150 -> 9136.7351 | R13: =G13*(1+0.06)^K13 -> 67032.538 | S13: =Q13/R13 -> 0.13630299 | V13: i' | W13: =(1+W8)/(1+W9)-1 -> 0.0089639327
A14: 0000093 | B14: 94076500365 | C14: 650608 | D14: =_xlfn.CONCAT(MID(C14,5,2),"/",MID(C14,3,2),"/",MID(C14,1,2)) -> 08/06/65 | E14: 12/03/2007 | F14: 8494.976 | G14: =IF(F14=0,$Y$3,F14) -> 8494.976 | H14: =_xlfn.NUMBERVALUE(MID(B14,3,2)) -> 7 | I14: =2022-YEAR(D14) -> 57 | J14: =2022-YEAR(E14) -> 15 | K14: =65-I14 -> 8 | L14: =IF(H14>22,122-H14,22-H14) -> 15 | M14: =L14+K14 -> 23 | N14: =G14*(1+0.06)^-J14 -> 3544.6567 | O14: =(((1-((1+$W$11)/(1+$W$10))^(6*(J14+K14)))/($W$10-$W$11))*(1+$W$10)^(6*(J14+K14))) -> 582.23207 | P14: =N14*0.065*O14 -> 134147.83 | Q14: =P14/150 -> 894.31888 | R14: =G14*(1+0.06)^K14 -> 13539.701 | S14: =Q14/R14 -> 0.066051597
A15: 0000098 | B15: 92028527627 | C15: 850415 | D15: =_xlfn.CONCAT(MID(C15,5,2),"/",MID(C15,3,2),"/",MID(C15,1,2)) -> 15/04/85 | E15: 16/07/2007 | F15: 25788.928 | G15: =IF(F15=0,$Y$3,F15) -> 25788.928 | H15: =_xlfn.NUMBERVALUE(MID(B15,3,2)) -> 2 | I15: =2022-YEAR(D15) -> 37 | J15: =2022-YEAR(E15) -> 15 | K15: =65-I15 -> 28 | L15: =IF(H15>22,122-H15,22-H15) -> 20 | M15: =L15+K15 -> 48 | N15: =G15*(1+0.06)^-J15 -> 10760.819 | O15: =(((1-((1+$W$11)/(1+$W$10))^(6*(J15+K15)))/($W$10-$W$11))*(1+$W$10)^(6*(J15+K15))) -> 3853.3236 | P15: =N15*0.065*O15 -> 2695219.6 | Q15: =P15/150 -> 17968.13 | R15: =G15*(1+0.06)^K15 -> 131824.92 | S15: =Q15/R15 -> 0.13630299
A16: 0000101 | B16: 37998008868 | C16: 800605 | D16: =_xlfn.CONCAT(MID(C16,5,2),"/",MID(C16,3,2),"/",MID(C16,1,2)) -> 05/06/80 | E16: 24/09/2007 | F16: 12843.392 | G16: =IF(F16=0,$Y$3,F16) -> 12843.392 | H16: =_xlfn.NUMBERVALUE(MID(B16,3,2)) -> 99 | I16: =2022-YEAR(D16) -> 42 | J16: =2022-YEAR(E16) -> 15 | K16: =65-I16 -> 23 | L16: =IF(H16>22,122-H16,22-H16) -> 23 | M16: =L16+K16 -> 46 | N16: =G16*(1+0.06)^-J16 -> 5359.0987 | O16: =(((1-((1+$W$11)/(1+$W$10))^(6*(J16+K16)))/($W$10-$W$11))*(1+$W$10)^(6*(J16+K16))) -> 2481.8865 | P16: =N16*0.065*O16 -> 864543.88 | Q16: =P16/150 -> 5763.6258 | R16: =G16*(1+0.06)^K16 -> 49058.542 | S16: =Q16/R16 -> 0.11748465
A17: 0000108 | B17: 45986302219 | C17: 631113 | D17: =_xlfn.CONCAT(MID(C17,5,2),"/",MID(C17,3,2),"/",MID(C17,1,2)) -> 13/11/63 | E17: 07/04/2008 | F17: 5906.112 | G17: =IF(F17=0,$Y$3,F17) -> 5906.112 | H17: =_xlfn.NUMBERVALUE(MID(B17,3,2)) -> 98 | I17: =2022-YEAR(D17) -> 59 | J17: =2022-YEAR(E17) -> 14 | K17: =65-I17 -> 6 | L17: =IF(H17>22,122-H17,22-H17) -> 24 | M17: =L17+K17 -> 30 | N17: =G17*(1+0.06)^-J17 -> 2612.279 | O17: =(((1-((1+$W$11)/(1+$W$10))^(6*(J17+K17)))/($W$10-$W$11))*(1+$W$10)^(6*(J17+K17))) -> 418.9461 | P17: =N17*0.065*O17 -> 71136.267 | Q17: =P17/150 -> 474.24178 | R17: =G17*(1+0.06)^K17 -> 8377.9328 | S17: =Q17/R17 -> 0.056606062
